Workbook

Sheet LS09
A1: LS09 | P1: G1 | Q1: =F15+J15 -> 43858.403 | T1: G2 | U1: =F15+J16 -> 43858
AI2: Processed
B3: Exp No: | C3: =$A$1 -> LS09 | J3: Date: | K3: 43861 | O3: Embryo No | P3: Im.View / Laser | Q3: Time | U3: Total Tricaine Time (min) | V3: Stage when imaged [hpf] | W3: Notes | Y3: Exp No | Z3: Strain | AA3: Stage | AB3: Manip. | AC3: Date | AD3: n Total | AE3: mt | AF3: ht | AG3: wt | AH3: Include? | AI3: mt | AJ3: ht | AK3: wt | AM3: Pos | AN3: =A1 -> LS09
B4: Strain: | C4: hapln1a prom241/+ (F2s) InX | J4: Stage: | K4: 72-74 | Q4: Tricaine/Cold | R4: Mount | S4: Chamber | T4: Imaged | Y4: =C3 -> LS09 | Z4: =C4 -> hapln1a prom241/+ (F2s) InX | AA4: =K4 -> 72-74 | AB4: None | AC4: =K3 -> 43861 | AD4: =E13 -> 18 | AE4: =H13 -> 3 | AF4: =J13 -> 11 | AG4: =L13 -> 4 | AH4: YES | AI4: =H20 -> 3 | AJ4: =J20 -> 4 | AK4: =L20 -> 3 | AM4: Gene | AN4: =B6 -> hapln1a
C5: 1 | D5: 2 | E5: 3 | F5: 4 | G5: 5 | H5: 6 | I5: 7 | J5: 8 | K5: 9 | L5: 10 | N5: 1 | O5: F01 | P5: Ventral | Q5: 0.40277778 | R5: 0.40625 | S5: 0.41319444 | T5: 0.41944444 | U5: =T5-Q5 -> 0.016666667 | V5: =(($K$3+T5)-$Q$1)*24 -> 72.4 | AM5: F01 | AN5: {=TRANSPOSE(C6:L6)} -> ht
B6: hapln1a | C6: ht | D6: ht | E6: ht | F6: ht | G6: ht | H6: ht | I6: wt | J6: ht | K6: ht | L6: mt | O6: F02 | P6: Ventral | Q6: =Q5 -> 0.40277778 | R6: =R5 -> 0.40625 | S6: =S5 -> 0.41319444 | T6: 0.425 | U6: =T6-Q6 -> 0.022222222 | V6: =(($K$3+T6)-$Q$1)*24 -> 72.533333 | AM6: F02 | AN6: ht
C7: 11 | D7: 12 | E7: 13 | F7: 14 | G7: 15 | H7: 16 | I7: 17 | J7: 18 | K7: 19 | L7: 20 | O7: F03 | P7: Ventral | Q7: =Q5 -> 0.40277778 | R7: =R5 -> 0.40625 | S7: =S5 -> 0.41319444 | T7: 0.43333333 | U7: =T7-Q7 -> 0.030555556 | V7: =(($K$3+T7)-$Q$1)*24 -> 72.733333 | AM7: F03 | AN7: ht
C8: mt | D8: wt | E8: ht | F8: ht | G8: wt | H8: ht | I8: wt | J8: mt | K8: X | L8: X | N8: 2 | O8: F04 | P8: Ventral | Q8: 0.41666667 | R8: 0.425 | S8: 0.4375 | T8: 0.43958333 | U8: =T8-Q8 -> 0.022916667 | V8: =(($K$3+T8)-$Q$1)*24 -> 72.883333 | AM8: F04 | AN8: ht
C9: 21 | D9: 22 | E9: 23 | F9: 24 | G9: 25 | H9: 26 | I9: 27 | J9: 28 | K9: 29 | L9: 30 | O9: F05 | P9: Ventral | Q9: =Q8 -> 0.41666667 | R9: =R8 -> 0.425 | S9: =S8 -> 0.4375 | T9: 0.44583333 | U9: =T9-Q9 -> 0.029166667 | V9: =(($K$3+T9)-$Q$1)*24 -> 73.033333 | AM9: F05 | AN9: ht
B10: Gene: | C10: X | D10: X | E10: X | F10: X | G10: X | H10: X | I10: X | J10: X | K10: X | L10: X | O10: F06 | P10: Ventral | Q10: =Q8 -> 0.41666667 | R10: =R8 -> 0.425 | S10: =S8 -> 0.4375 | T10: 0.45069444 | U10: =T10-Q10 -> 0.034027778 | V10: =(($K$3+T10)-$Q$1)*24 -> 73.15 | AM10: F06 | AN10: ht
C11: 31 | D11: 32 | E11: 33 | F11: 34 | G11: 35 | H11: 36 | I11: 37 | J11: 38 | K11: 39 | L11: 40 | N11: 3 | O11: F07 | P11: Ventral | Q11: 0.43819444 | R11: 0.44583333 | S11: 0.45138889 | T11: 0.46597222 | U11: =T11-Q11 -> 0.027777778 | V11: =(($K$3+T11)-$Q$1)*24 -> 73.516667 | AM11: F07 | AN11: wt
C12: X | D12: X | E12: X | F12: X | G12: X | H12: X | I12: X | J12: X | K12: X | L12: X | O12: F08 | P12: Ventral | Q12: =Q11 -> 0.43819444 | R12: =R11 -> 0.44583333 | S12: =S11 -> 0.45138889 | T12: 0.47152778 | U12: =T12-Q12 -> 0.033333333 | V12: =(($K$3+T12)-$Q$1)*24 -> 73.65 | AM12: F08 | AN12: ht
C13: Total: | E13: =H13+J13+L13 -> 18 | G13: mt | H13: =COUNTIF(C6:L12,"*"&G13&"*") -> 3 | I13: ht | J13: =COUNTIF(C6:L12,"*"&I13&"*") -> 11 | K13: wt | L13: =COUNTIF(C6:L12,"*"&K13&"*") -> 4 | O13: F09 | P13: Ventral | Q13: =Q11 -> 0.43819444 | R13: =R11 -> 0.44583333 | S13: =S11 -> 0.45138889 | T13: 0.47708333 | U13: =T13-Q13 -> 0.038888889 | V13: =(($K$3+T13)-$Q$1)*24 -> 73.783333 | AM13: F09 | AN13: ht
N14: 4 | O14: F10 | P14: Ventral | Q14: 0.45833333 | R14: 0.47847222 | S14: 0.48263889 | T14: 0.48472222 | U14: =T14-Q14 -> 0.026388889 | V14: =(($K$3+T14)-$Q$1)*24 -> 73.966667 | AM14: F10 | AN14: mt
C15: Notes: | E15: DOB: | F15: 43858 | H15: fert: | I15: G1: | J15: 0.40277778 | K15: All | O15: F11 | P15: Ventral | Q15: =Q14 -> 0.45833333 | R15: =R14 -> 0.47847222 | S15: =S14 -> 0.48263889 | T15: 0.48958333 | U15: =T15-Q15 -> 0.03125 | V15: =(($K$3+T15)-$Q$1)*24 -> 74.083333 | AM15: F11 | AN15: {=TRANSPOSE(C8:L8)} -> mt
I16: G2: | O16: F12 | P16: Ventral | Q16: =Q14 -> 0.45833333 | R16: =R14 -> 0.47847222 | S16: =S14 -> 0.48263889 | T16: 0.49791667 | U16: =T16-Q16 -> 0.039583333 | V16: =(($K$3+T16)-$Q$1)*24 -> 74.283333 | AM16: F12 | AN16: wt
N17: 5 | O17: F13 | P17: Ventral | Q17: 0.48472222 | R17: 0.48958333 | S17: 0.5 | T17: 0.50347222 | U17: =T17-Q17 -> 0.01875 | V17: =(($K$3+T17)-$Q$1)*24 -> 74.416667 | AM17: F13 | AN17: ht
C18: Started imaging at 9:45. Ended: 1:15pm | P18: Dorsal | Q18: =Q17 -> 0.48472222 | R18: =R17 -> 0.48958333 | S18: =S17 -> 0.5 | T18: 0.50625 | U18: =T18-Q18 -> 0.021527778 | V18: =(($K$3+T18)-$Q$1)*24 -> 74.483333 | AM18: F14 | AN18: ht
O19: F14 | P19: Ventral | Q19: =Q17 -> 0.48472222 | R19: =R17 -> 0.48958333 | S19: =S17 -> 0.5 | T19: 0.51319444 | U19: =T19-Q19 -> 0.028472222 | V19: =(($K$3+T19)-$Q$1)*24 -> 74.65 | AM19: F15 | AN19: wt
C20: Processed: | G20: mt | H20: 3 | I20: ht | J20: 4 | K20: wt | L20: 3 | P20: Dorsal | Q20: =Q17 -> 0.48472222 | R20: =R17 -> 0.48958333 | S20: =S17 -> 0.5 | T20: 0.51805556 | U20: =T20-Q20 -> 0.033333333 | V20: =(($K$3+T20)-$Q$1)*24 -> 74.766667 | AM20: F16 | AN20: ht
O21: F15 | P21: Ventral | Q21: =Q17 -> 0.48472222 | R21: =R17 -> 0.48958333 | S21: =S17 -> 0.5 | T21: 0.525 | U21: =T21-Q21 -> 0.040277778 | V21: =(($K$3+T21)-$Q$1)*24 -> 74.933333 | AM21: F17 | AN21: wt
C22: Longer than: | G22: 0.020833333 | I22: min | N22: 6 | O22: F16 | P22: Ventral | Q22: 0.50208333 | R22: 0.51041667 | S22: 0.53125 | T22: 0.52986111 | U22: =T22-Q22 -> 0.027777778 | V22: =(($K$3+T22)-$Q$1)*24 -> 75.05 | AM22: F18 | AN22: mt
O23: F17 | P23: Ventral | Q23: =Q22 -> 0.50208333 | R23: =R22 -> 0.51041667 | S23: =S22 -> 0.53125 | T23: 0.53402778 | U23: =T23-Q23 -> 0.031944444 | V23: =(($K$3+T23)-$Q$1)*24 -> 75.15 | AM23: F19 | AN23: X
O24: F18 | P24: Ventral | Q24: =Q22 -> 0.50208333 | R24: =R22 -> 0.51041667 | S24: =S22 -> 0.53125 | T24: 0.54097222 | U24: =T24-Q24 -> 0.038888889 | V24: =(($K$3+T24)-$Q$1)*24 -> 75.316667 | AM24: F20 | AN24: X
P25: Dorsal | Q25: =Q22 -> 0.50208333 | R25: =R22 -> 0.51041667 | S25: =S22 -> 0.53125 | T25: 0.54375 | U25: =T25-Q25 -> 0.041666667 | V25: =(($K$3+T25)-$Q$1)*24 -> 75.383333 | AM25: F21 | AN25: {=TRANSPOSE(C10:L10)} -> X
AM26: F22 | AN26: X
AM27: F23 | AN27: X
AM28: F24 | AN28: X
AM29: F25 | AN29: X
AM30: F26 | AN30: X
AM31: F27 | AN31: X
AM32: F28 | AN32: X
AM33: F29 | AN33: X
AM34: F30 | AN34: X
AM35: F31 | AN35: {=TRANSPOSE(C12:L12)} -> X
AM36: F32 | AN36: X
AM37: F33 | AN37: X
AM38: F34 | AN38: X
AM39: F35 | AN39: X
AM40: F36 | AN40: X
...

Sheet Formatx4x1gt
P1: G1 | Q1: =F15+J15 -> 0 | T1: G2 | U1: =F15+J16 -> 0 | W1: =MAX(V5:V44) -> 0
AI2: Processed
B3: Exp No: | C3: =A1 -> 0 | J3: Date: | O3: Embryo No | P3: Im.View / Laser | Q3: Time | U3: Total Tricaine Time (min) | V3: Stage when imaged [hpf] | W3: Notes | Y3: Exp No | Z3: Strain | AA3: Stage | AB3: Manip. | AC3: Date | AD3: n Total | AE3: mt | AF3: ht | AG3: wt | AH3: Include? | AI3: mt | AJ3: ht | AK3: wt | AM3: Pos | AN3: =A1 -> 0
B4: Strain: | J4: Stage: | Q4: Tricaine/Cold | R4: Mount | S4: Chamber | T4: Imaged | Y4: =C3 -> 0 | Z4: =C4 -> 0 | AA4: =K4 -> 0 | AB4: None | AC4: =K3 -> 0 | AD4: =E13 -> 0 | AE4: =H13 -> 0 | AF4: =J13 -> 0 | AG4: =L13 -> 0 | AH4: YES | AI4: =H20 -> 0 | AJ4: =J20 -> 0 | AK4: =L20 -> 0 | AM4: Gene | AN4: =B6 -> 0
C5: 1 | D5: 2 | E5: 3 | F5: 4 | G5: 5 | H5: 6 | I5: 7 | J5: 8 | K5: 9 | L5: 10 | N5: 1 | O5: F01 | P5: Ventral | U5: =T5-Q5 -> 0 | V5: =(($K$3+T5)-$Q$1)*24 -> 0 | AM5: F01 | AN5: {=TRANSPOSE(C6:L6)} -> X
C6: X | D6: X | E6: X | F6: X | G6: X | H6: X | I6: X | J6: X | K6: X | L6: X | O6: F02 | P6: Ventral | Q6: =Q5 -> 0 | R6: =R5 -> 0 | S6: =S5 -> 0 | U6: =T6-Q6 -> 0 | V6: =(($K$3+T6)-$Q$1)*24 -> 0 | AM6: F02 | AN6: X
C7: 11 | D7: 12 | E7: 13 | F7: 14 | G7: 15 | H7: 16 | I7: 17 | J7: 18 | K7: 19 | L7: 20 | O7: F03 | P7: Ventral | Q7: =Q6 -> 0 | R7: =R6 -> 0 | S7: =S6 -> 0 | U7: =T7-Q7 -> 0 | V7: =(($K$3+T7)-$Q$1)*24 -> 0 | AM7: F03 | AN7: X
C8: X | D8: X | E8: X | F8: X | G8: X | H8: X | I8: X | J8: X | K8: X | L8: X | O8: F04 | P8: Ventral | Q8: =Q7 -> 0 | R8: =R7 -> 0 | S8: =S7 -> 0 | U8: =T8-Q8 -> 0 | V8: =(($K$3+T8)-$Q$1)*24 -> 0 | AM8: F04 | AN8: X
C9: 21 | D9: 22 | E9: 23 | F9: 24 | G9: 25 | H9: 26 | I9: 27 | J9: 28 | K9: 29 | L9: 30 | N9: 2 | O9: F05 | P9: Ventral | U9: =T9-Q9 -> 0 | V9: =(($K$3+T9)-$Q$1)*24 -> 0 | AM9: F05 | AN9: X
B10: Gene: | C10: X | D10: X | E10: X | F10: X | G10: X | H10: X | I10: X | J10: X | K10: X | L10: X | O10: F06 | P10: Ventral | Q10: =Q9 -> 0 | R10: =R9 -> 0 | S10: =S9 -> 0 | U10: =T10-Q10 -> 0 | V10: =(($K$3+T10)-$Q$1)*24 -> 0 | AM10: F06 | AN10: X
C11: 31 | D11: 32 | E11: 33 | F11: 34 | G11: 35 | H11: 36 | I11: 37 | J11: 38 | K11: 39 | L11: 40 | O11: F07 | P11: Ventral | Q11: =Q10 -> 0 | R11: =R10 -> 0 | S11: =S10 -> 0 | U11: =T11-Q11 -> 0 | V11: =(($K$3+T11)-$Q$1)*24 -> 0 | AM11: F07 | AN11: X
C12: X | D12: X | E12: X | F12: X | G12: X | H12: X | I12: X | J12: X | K12: X | L12: X | O12: F08 | P12: Ventral | Q12: =Q11 -> 0 | R12: =R11 -> 0 | S12: =S11 -> 0 | U12: =T12-Q12 -> 0 | V12: =(($K$3+T12)-$Q$1)*24 -> 0 | AM12: F08 | AN12: X
C13: Total: | E13: =H13+J13+L13 -> 0 | G13: mt | H13: =COUNTIF(C6:L12,"*"&G13&"*") -> 0 | I13: ht | J13: =COUNTIF(C6:L12,"*"&I13&"*") -> 0 | K13: wt | L13: =COUNTIF(C6:L12,"*"&K13&"*") -> 0 | N13: 3 | O13: F09 | P13: Ventral | U13: =T13-Q13 -> 0 | V13: =(($K$3+T13)-$Q$1)*24 -> 0 | AM13: F09 | AN13: X
O14: F10 | P14: Ventral | Q14: =Q13 -> 0 | R14: =R13 -> 0 | S14: =S13 -> 0 | U14: =T14-Q14 -> 0 | V14: =(($K$3+T14)-$Q$1)*24 -> 0 | AM14: F10 | AN14: X
C15: Notes: | E15: DOB: | H15: fert: | I15: G1: | O15: F11 | P15: Ventral | Q15: =Q14 -> 0 | R15: =R14 -> 0 | S15: =S14 -> 0 | U15: =T15-Q15 -> 0 | V15: =(($K$3+T15)-$Q$1)*24 -> 0 | AM15: F11 | AN15: {=TRANSPOSE(C8:L8)} -> X
I16: G2: | O16: F12 | P16: Ventral | Q16: =Q15 -> 0 | R16: =R15 -> 0 | S16: =S15 -> 0 | U16: =T16-Q16 -> 0 | V16: =(($K$3+T16)-$Q$1)*24 -> 0 | AM16: F12 | AN16: X
N17: 4 | O17: F13 | P17: Ventral | U17: =T17-Q17 -> 0 | V17: =(($K$3+T17)-$Q$1)*24 -> 0 | AM17: F13 | AN17: X
O18: F14 | P18: Ventral | Q18: =Q17 -> 0 | R18: =R17 -> 0 | S18: =S17 -> 0 | U18: =T18-Q18 -> 0 | V18: =(($K$3+T18)-$Q$1)*24 -> 0 | AM18: F14 | AN18: X
O19: F15 | P19: Ventral | Q19: =Q18 -> 0 | R19: =R18 -> 0 | S19: =S18 -> 0 | U19: =T19-Q19 -> 0 | V19: =(($K$3+T19)-$Q$1)*24 -> 0 | AM19: F15 | AN19: X
C20: Processed: | G20: mt | I20: ht | K20: wt | O20: F16 | P20: Ventral | Q20: =Q19 -> 0 | R20: =R19 -> 0 | S20: =S19 -> 0 | U20: =T20-Q20 -> 0 | V20: =(($K$3+T20)-$Q$1)*24 -> 0 | AM20: F16 | AN20: X
N21: 5 | O21: F17 | P21: Ventral | U21: =T21-Q21 -> 0 | V21: =(($K$3+T21)-$Q$1)*24 -> 0 | AM21: F17 | AN21: X
C22: Longer than: | G22: 0.020833333 | I22: min | O22: F18 | P22: Ventral | Q22: =Q21 -> 0 | R22: =R21 -> 0 | S22: =S21 -> 0 | U22: =T22-Q22 -> 0 | V22: =(($K$3+T22)-$Q$1)*24 -> 0 | AM22: F18 | AN22: X
O23: F19 | P23: Ventral | Q23: =Q22 -> 0 | R23: =R22 -> 0 | S23: =S22 -> 0 | U23: =T23-Q23 -> 0 | V23: =(($K$3+T23)-$Q$1)*24 -> 0 | AM23: F19 | AN23: X
O24: F20 | P24: Ventral | Q24: =Q23 -> 0 | R24: =R23 -> 0 | S24: =S23 -> 0 | U24: =T24-Q24 -> 0 | V24: =(($K$3+T24)-$Q$1)*24 -> 0 | AM24: F20 | AN24: X
N25: 6 | O25: F21 | P25: Ventral | U25: =T25-Q25 -> 0 | V25: =(($K$3+T25)-$Q$1)*24 -> 0 | AM25: F21 | AN25: {=TRANSPOSE(C10:L10)} -> X
O26: F22 | P26: Ventral | Q26: =Q25 -> 0 | R26: =R25 -> 0 | S26: =S25 -> 0 | U26: =T26-Q26 -> 0 | V26: =(($K$3+T26)-$Q$1)*24 -> 0 | AM26: F22 | AN26: X
O27: F23 | P27: Ventral | Q27: =Q26 -> 0 | R27: =R26 -> 0 | S27: =S26 -> 0 | U27: =T27-Q27 -> 0 | V27: =(($K$3+T27)-$Q$1)*24 -> 0 | AM27: F23 | AN27: X
O28: F24 | P28: Ventral | Q28: =Q27 -> 0 | R28: =R27 -> 0 | S28: =S27 -> 0 | U28: =T28-Q28 -> 0 | V28: =(($K$3+T28)-$Q$1)*24 -> 0 | AM28: F24 | AN28: X
N29: 7 | O29: F25 | P29: Ventral | U29: =T29-Q29 -> 0 | V29: =(($K$3+T29)-$Q$1)*24 -> 0 | AM29: F25 | AN29: X
O30: F26 | P30: Ventral | Q30: =Q29 -> 0 | R30: =R29 -> 0 | S30: =S29 -> 0 | U30: =T30-Q30 -> 0 | V30: =(($K$3+T30)-$Q$1)*24 -> 0 | AM30: F26 | AN30: X
O31: F27 | P31: Ventral | Q31: =Q30 -> 0 | R31: =R30 -> 0 | S31: =S30 -> 0 | U31: =T31-Q31 -> 0 | V31: =(($K$3+T31)-$Q$1)*24 -> 0 | AM31: F27 | AN31: X
O32: F28 | P32: Ventral | Q32: =Q31 -> 0 | R32: =R31 -> 0 | S32: =S31 -> 0 | U32: =T32-Q32 -> 0 | V32: =(($K$3+T32)-$Q$1)*24 -> 0 | AM32: F28 | AN32: X
N33: 8 | O33: F29 | P33: Ventral | U33: =T33-Q33 -> 0 | V33: =(($K$3+T33)-$Q$1)*24 -> 0 | AM33: F29 | AN33: X
O34: F30 | P34: Ventral | Q34: =Q33 -> 0 | R34: =R33 -> 0 | S34: =S33 -> 0 | U34: =T34-Q34 -> 0 | V34: =(($K$3+T34)-$Q$1)*24 -> 0 | AM34: F30 | AN34: X
O35: F31 | P35: Ventral | Q35: =Q34 -> 0 | R35: =R34 -> 0 | S35: =S34 -> 0 | U35: =T35-Q35 -> 0 | V35: =(($K$3+T35)-$Q$1)*24 -> 0 | AM35: F31 | AN35: {=TRANSPOSE(C12:L12)} -> X
O36: F32 | P36: Ventral | Q36: =Q35 -> 0 | R36: =R35 -> 0 | S36: =S35 -> 0 | U36: =T36-Q36 -> 0 | V36: =(($K$3+T36)-$Q$1)*24 -> 0 | AM36: F32 | AN36: X
N37: 9 | O37: F33 | P37: Ventral | U37: =T37-Q37 -> 0 | V37: =(($K$3+T37)-$Q$1)*24 -> 0 | AM37: F33 | AN37: X
O38: F34 | P38: Ventral | Q38: =Q37 -> 0 | R38: =R37 -> 0 | S38: =S37 -> 0 | U38: =T38-Q38 -> 0 | V38: =(($K$3+T38)-$Q$1)*24 -> 0 | AM38: F34 | AN38: X
O39: F35 | P39: Ventral | Q39: =Q38 -> 0 | R39: =R38 -> 0 | S39: =S38 -> 0 | U39: =T39-Q39 -> 0 | V39: =(($K$3+T39)-$Q$1)*24 -> 0 | AM39: F35 | AN39: X
O40: F36 | P40: Ventral | Q40: =Q39 -> 0 | R40: =R39 -> 0 | S40: =S39 -> 0 | U40: =T40-Q40 -> 0 | V40: =(($K$3+T40)-$Q$1)*24 -> 0 | AM40: F36 | AN40: X
...

Sheet Formatx4x2gt
P1: G1 | Q1: =F25+J25 -> 0 | T1: G2 | U1: =F25+J26 -> 0 | W1: =MAX(V5:V44) -> 0
AI2: Processed
B3: Exp No: | C3: =A1 -> 0 | J3: Date: | O3: Embryo No | P3: Im.View / Laser | Q3: Time | U3: Total Tricaine Time (min) | V3: Stage when imaged [hpf] | W3: Notes | Y3: Exp No | Z3: Strain | AA3: Stage | AB3: Manip. | AC3: Date | AD3: n Total | AE3: mt | AF3: ht | AG3: wt | AH3: Include? | AI3: mt | AJ3: ht | AK3: wt | AM3: Pos | AN3: =A1 -> 0 | AO3: =A1 -> 0
B4: Strain: | J4: Stage: | Q4: Tricaine/Cold | R4: Mount | S4: Chamber | T4: Imaged | Y4: =C3 -> 0 | Z4: =C4 -> 0 | AA4: =K4 -> 0 | AB4: None | AC4: =K3 -> 0 | AD4: =E13 -> 0 | AE4: =H29 -> 0 | AF4: =J29 -> 0 | AG4: =L29 -> 0 | AH4: YES | AI4: =H31 -> 0 | AJ4: =J31 -> 0 | AK4: =L31 -> 0 | AM4: Gene | AN4: =B6 -> 0 | AO4: =B16 -> 0
C5: 1 | D5: 2 | E5: 3 | F5: 4 | G5: 5 | H5: 6 | I5: 7 | J5: 8 | K5: 9 | L5: 10 | N5: 1 | O5: F01 | P5: Ventral | U5: =T5-Q5 -> 0 | V5: =(($K$3+T5)-$Q$1)*24 -> 0 | AM5: F01 | AN5: {=TRANSPOSE(C6:L6)} -> X | AO5: {=TRANSPOSE(C16:L16)} -> X
C6: X | D6: X | E6: X | F6: X | G6: X | H6: X | I6: X | J6: X | K6: X | L6: X | O6: F02 | P6: Ventral | Q6: =Q5 -> 0 | R6: =R5 -> 0 | S6: =S5 -> 0 | U6: =T6-Q6 -> 0 | V6: =(($K$3+T6)-$Q$1)*24 -> 0 | AM6: F02 | AN6: X | AO6: X
C7: 11 | D7: 12 | E7: 13 | F7: 14 | G7: 15 | H7: 16 | I7: 17 | J7: 18 | K7: 19 | L7: 20 | O7: F03 | P7: Ventral | Q7: =Q6 -> 0 | R7: =R6 -> 0 | S7: =S6 -> 0 | U7: =T7-Q7 -> 0 | V7: =(($K$3+T7)-$Q$1)*24 -> 0 | AM7: F03 | AN7: X | AO7: X
C8: X | D8: X | E8: X | F8: X | G8: X | H8: X | I8: X | J8: X | K8: X | L8: X | O8: F04 | P8: Ventral | Q8: =Q7 -> 0 | R8: =R7 -> 0 | S8: =S7 -> 0 | U8: =T8-Q8 -> 0 | V8: =(($K$3+T8)-$Q$1)*24 -> 0 | AM8: F04 | AN8: X | AO8: X
C9: 21 | D9: 22 | E9: 23 | F9: 24 | G9: 25 | H9: 26 | I9: 27 | J9: 28 | K9: 29 | L9: 30 | N9: 2 | O9: F05 | P9: Ventral | U9: =T9-Q9 -> 0 | V9: =(($K$3+T9)-$Q$1)*24 -> 0 | AM9: F05 | AN9: X | AO9: X
B10: Gene: | C10: X | D10: X | E10: X | F10: X | G10: X | H10: X | I10: X | J10: X | K10: X | L10: X | O10: F06 | P10: Ventral | Q10: =Q9 -> 0 | R10: =R9 -> 0 | S10: =S9 -> 0 | U10: =T10-Q10 -> 0 | V10: =(($K$3+T10)-$Q$1)*24 -> 0 | AM10: F06 | AN10: X | AO10: X
C11: 31 | D11: 32 | E11: 33 | F11: 34 | G11: 35 | H11: 36 | I11: 37 | J11: 38 | K11: 39 | L11: 40 | O11: F07 | P11: Ventral | Q11: =Q10 -> 0 | R11: =R10 -> 0 | S11: =S10 -> 0 | U11: =T11-Q11 -> 0 | V11: =(($K$3+T11)-$Q$1)*24 -> 0 | AM11: F07 | AN11: X | AO11: X
C12: X | D12: X | E12: X | F12: X | G12: X | H12: X | I12: X | J12: X | K12: X | L12: X | O12: F08 | P12: Ventral | Q12: =Q11 -> 0 | R12: =R11 -> 0 | S12: =S11 -> 0 | U12: =T12-Q12 -> 0 | V12: =(($K$3+T12)-$Q$1)*24 -> 0 | AM12: F08 | AN12: X | AO12: X
C13: Total: | E13: =H13+J13+L13 -> 0 | G13: mt | H13: =COUNTIF(C6:L12,"*"&G13&"*") -> 0 | I13: ht | J13: =COUNTIF(C6:L12,"*"&I13&"*") -> 0 | K13: wt | L13: =COUNTIF(C6:L12,"*"&K13&"*") -> 0 | N13: 3 | O13: F09 | P13: Ventral | U13: =T13-Q13 -> 0 | V13: =(($K$3+T13)-$Q$1)*24 -> 0 | AM13: F09 | AN13: X | AO13: X
O14: F10 | P14: Ventral | Q14: =Q13 -> 0 | R14: =R13 -> 0 | S14: =S13 -> 0 | U14: =T14-Q14 -> 0 | V14: =(($K$3+T14)-$Q$1)*24 -> 0 | AM14: F10 | AN14: X | AO14: X
C15: 1 | D15: 2 | E15: 3 | F15: 4 | G15: 5 | H15: 6 | I15: 7 | J15: 8 | K15: 9 | L15: 10 | O15: F11 | P15: Ventral | Q15: =Q14 -> 0 | R15: =R14 -> 0 | S15: =S14 -> 0 | U15: =T15-Q15 -> 0 | V15: =(($K$3+T15)-$Q$1)*24 -> 0 | AM15: F11 | AN15: {=TRANSPOSE(C8:L8)} -> X | AO15: {=TRANSPOSE(C18:L18)} -> X
C16: X | D16: X | E16: X | F16: X | G16: X | H16: X | I16: X | J16: X | K16: X | L16: X | O16: F12 | P16: Ventral | Q16: =Q15 -> 0 | R16: =R15 -> 0 | S16: =S15 -> 0 | U16: =T16-Q16 -> 0 | V16: =(($K$3+T16)-$Q$1)*24 -> 0 | AM16: F12 | AN16: X | AO16: X
C17: 11 | D17: 12 | E17: 13 | F17: 14 | G17: 15 | H17: 16 | I17: 17 | J17: 18 | K17: 19 | L17: 20 | N17: 4 | O17: F13 | P17: Ventral | U17: =T17-Q17 -> 0 | V17: =(($K$3+T17)-$Q$1)*24 -> 0 | AM17: F13 | AN17: X | AO17: X
C18: X | D18: X | E18: X | F18: X | G18: X | H18: X | I18: X | J18: X | K18: X | L18: X | O18: F14 | P18: Ventral | Q18: =Q17 -> 0 | R18: =R17 -> 0 | S18: =S17 -> 0 | U18: =T18-Q18 -> 0 | V18: =(($K$3+T18)-$Q$1)*24 -> 0 | AM18: F14 | AN18: X | AO18: X
C19: 21 | D19: 22 | E19: 23 | F19: 24 | G19: 25 | H19: 26 | I19: 27 | J19: 28 | K19: 29 | L19: 30 | O19: F15 | P19: Ventral | Q19: =Q18 -> 0 | R19: =R18 -> 0 | S19: =S18 -> 0 | U19: =T19-Q19 -> 0 | V19: =(($K$3+T19)-$Q$1)*24 -> 0 | AM19: F15 | AN19: X | AO19: X
B20: Gene: | C20: X | D20: X | E20: X | F20: X | G20: X | H20: X | I20: X | J20: X | K20: X | L20: X | O20: F16 | P20: Ventral | Q20: =Q19 -> 0 | R20: =R19 -> 0 | S20: =S19 -> 0 | U20: =T20-Q20 -> 0 | V20: =(($K$3+T20)-$Q$1)*24 -> 0 | AM20: F16 | AN20: X | AO20: X
C21: 31 | D21: 32 | E21: 33 | F21: 34 | G21: 35 | H21: 36 | I21: 37 | J21: 38 | K21: 39 | L21: 40 | N21: 5 | O21: F17 | P21: Ventral | U21: =T21-Q21 -> 0 | V21: =(($K$3+T21)-$Q$1)*24 -> 0 | AM21: F17 | AN21: X | AO21: X
C22: X | D22: X | E22: X | F22: X | G22: X | H22: X | I22: X | J22: X | K22: X | L22: X | O22: F18 | P22: Ventral | Q22: =Q21 -> 0 | R22: =R21 -> 0 | S22: =S21 -> 0 | U22: =T22-Q22 -> 0 | V22: =(($K$3+T22)-$Q$1)*24 -> 0 | AM22: F18 | AN22: X | AO22: X
C23: Total: | E23: =H23+J23+L23 -> 0 | G23: mt | H23: =COUNTIF(C16:L22,"*"&G23&"*") -> 0 | I23: ht | J23: =COUNTIF(C16:L22,"*"&I23&"*") -> 0 | K23: wt | L23: =COUNTIF(C16:L22,"*"&K23&"*") -> 0 | O23: F19 | P23: Ventral | Q23: =Q22 -> 0 | R23: =R22 -> 0 | S23: =S22 -> 0 | U23: =T23-Q23 -> 0 | V23: =(($K$3+T23)-$Q$1)*24 -> 0 | AM23: F19 | AN23: X | AO23: X
O24: F20 | P24: Ventral | Q24: =Q23 -> 0 | R24: =R23 -> 0 | S24: =S23 -> 0 | U24: =T24-Q24 -> 0 | V24: =(($K$3+T24)-$Q$1)*24 -> 0 | AM24: F20 | AN24: X | AO24: X
C25: Notes: | E25: DOB: | H25: fert: | I25: G1: | N25: 6 | O25: F21 | P25: Ventral | U25: =T25-Q25 -> 0 | V25: =(($K$3+T25)-$Q$1)*24 -> 0 | AM25: F21 | AN25: {=TRANSPOSE(C10:L10)} -> X | AO25: {=TRANSPOSE(C20:L20)} -> X
I26: G2: | O26: F22 | P26: Ventral | Q26: =Q25 -> 0 | R26: =R25 -> 0 | S26: =S25 -> 0 | U26: =T26-Q26 -> 0 | V26: =(($K$3+T26)-$Q$1)*24 -> 0 | AM26: F22 | AN26: X | AO26: X
O27: F23 | P27: Ventral | Q27: =Q26 -> 0 | R27: =R26 -> 0 | S27: =S26 -> 0 | U27: =T27-Q27 -> 0 | V27: =(($K$3+T27)-$Q$1)*24 -> 0 | AM27: F23 | AN27: X | AO27: X
O28: F24 | P28: Ventral | Q28: =Q27 -> 0 | R28: =R27 -> 0 | S28: =S27 -> 0 | U28: =T28-Q28 -> 0 | V28: =(($K$3+T28)-$Q$1)*24 -> 0 | AM28: F24 | AN28: X | AO28: X
C29: Genot. Combined | G29: mt | H29: =COUNTIFS($AN$5:$AN$44,"mt",$AO$5:$AO$44,"mt") -> 0 | I29: ht | J29: =E23-H29-L29 -> 0 | K29: wt | L29: =COUNTIFS($AN$5:$AN$44,"wt",$AO$5:$AO$44,"wt") -> 0 | N29: 7 | O29: F25 | P29: Ventral | U29: =T29-Q29 -> 0 | V29: =(($K$3+T29)-$Q$1)*24 -> 0 | AM29: F25 | AN29: X | AO29: X
O30: F26 | P30: Ventral | Q30: =Q29 -> 0 | R30: =R29 -> 0 | S30: =S29 -> 0 | U30: =T30-Q30 -> 0 | V30: =(($K$3+T30)-$Q$1)*24 -> 0 | AM30: F26 | AN30: X | AO30: X
C31: Processed: | G31: mt | I31: ht | K31: wt | O31: F27 | P31: Ventral | Q31: =Q30 -> 0 | R31: =R30 -> 0 | S31: =S30 -> 0 | U31: =T31-Q31 -> 0 | V31: =(($K$3+T31)-$Q$1)*24 -> 0 | AM31: F27 | AN31: X | AO31: X
O32: F28 | P32: Ventral | Q32: =Q31 -> 0 | R32: =R31 -> 0 | S32: =S31 -> 0 | U32: =T32-Q32 -> 0 | V32: =(($K$3+T32)-$Q$1)*24 -> 0 | AM32: F28 | AN32: X | AO32: X
C33: Longer than: | G33: 0.020833333 | I33: min | N33: 8 | O33: F29 | P33: Ventral | U33: =T33-Q33 -> 0 | V33: =(($K$3+T33)-$Q$1)*24 -> 0 | AM33: F29 | AN33: X | AO33: X
O34: F30 | P34: Ventral | Q34: =Q33 -> 0 | R34: =R33 -> 0 | S34: =S33 -> 0 | U34: =T34-Q34 -> 0 | V34: =(($K$3+T34)-$Q$1)*24 -> 0 | AM34: F30 | AN34: X | AO34: X
O35: F31 | P35: Ventral | Q35: =Q34 -> 0 | R35: =R34 -> 0 | S35: =S34 -> 0 | U35: =T35-Q35 -> 0 | V35: =(($K$3+T35)-$Q$1)*24 -> 0 | AM35: F31 | AN35: {=TRANSPOSE(C12:L12)} -> X | AO35: {=TRANSPOSE(C22:L22)} -> X
O36: F32 | P36: Ventral | Q36: =Q35 -> 0 | R36: =R35 -> 0 | S36: =S35 -> 0 | U36: =T36-Q36 -> 0 | V36: =(($K$3+T36)-$Q$1)*24 -> 0 | AM36: F32 | AN36: X | AO36: X
N37: 9 | O37: F33 | P37: Ventral | U37: =T37-Q37 -> 0 | V37: =(($K$3+T37)-$Q$1)*24 -> 0 | AM37: F33 | AN37: X | AO37: X
O38: F34 | P38: Ventral | Q38: =Q37 -> 0 | R38: =R37 -> 0 | S38: =S37 -> 0 | U38: =T38-Q38 -> 0 | V38: =(($K$3+T38)-$Q$1)*24 -> 0 | AM38: F34 | AN38: X | AO38: X
O39: F35 | P39: Ventral | Q39: =Q38 -> 0 | R39: =R38 -> 0 | S39: =S38 -> 0 | U39: =T39-Q39 -> 0 | V39: =(($K$3+T39)-$Q$1)*24 -> 0 | AM39: F35 | AN39: X | AO39: X
O40: F36 | P40: Ventral | Q40: =Q39 -> 0 | R40: =R39 -> 0 | S40: =S39 -> 0 | U40: =T40-Q40 -> 0 | V40: =(($K$3+T40)-$Q$1)*24 -> 0 | AM40: F36 | AN40: X | AO40: X
...

Sheet All
N1: Processed
D2: All Lightsheet Data | J2: mt | K2: ht | L2: wt | N2: mt | O2: ht | P2: wt
J3: =SUBTOTAL(9,J8:J323) -> 0 | K3: =SUBTOTAL(9,K8:K323) -> 0 | L3: =SUBTOTAL(9,L8:L323) -> 0 | M3: =SUM(J3:L3) -> 0 | N3: =SUBTOTAL(9,N8:N323) -> 0 | O3: =SUBTOTAL(9,O8:O323) -> 0 | P3: =SUBTOTAL(9,P8:P323) -> 0 | Q3: =SUM(N3:P3) -> 0
N5: Processed
D6: LS No | E6: Strain | F6: Stage [hpf] | G6: Manip | H6: Date | I6: n Total | J6: mt | K6: ht | L6: wt | M6: Include? | N6: mt | O6: ht | P6: wt
B7: 0 | D7: ='LS09'!Y4 -> LS09 | E7: ='LS09'!Z4 -> hapln1a prom241/+ (F2s) InX | F7: ='LS09'!AA4 -> 72-74 | G7: ='LS09'!AB4 -> None | H7: ='LS09'!AC4 -> 43861 | I7: ='LS09'!AD4 -> 18 | J7: ='LS09'!AE4 -> 3 | K7: ='LS09'!AF4 -> 11 | ... P7: ='LS09'!AK4 -> 3
B8: 1
B9: 2
B10: 3
B11: 4
B12: 5
B13: 6
B14: 7
B15: 8
B16: 9
B17: 10
B18: 11
B19: 12
... B51: 44

Sheet RAW_All
A1: =All!D6 -> LS No | B1: =All!E6 -> Strain | C1: Stage | D1: Manipulation | E1: =All!H6 -> Date
A2: =All!D7 -> LS09 | B2: =All!E7 -> hapln1a prom241/+ (F2s) InX | C2: =All!F7 -> 72-74 | D2: =All!G7 -> None | E2: =All!H7 -> 43861
A3: =All!D8 -> 0 | B3: =All!E8 -> 0 | C3: =All!F8 -> 0 | D3: =All!G8 -> 0 | E3: =All!H8 -> 0
A4: =All!D9 -> 0 | B4: =All!E9 -> 0 | C4: =All!F9 -> 0 | D4: =All!G9 -> 0 | E4: =All!H9 -> 0
A5: =All!D10 -> 0 | B5: =All!E10 -> 0 | C5: =All!F10 -> 0 | D5: =All!G10 -> 0 | E5: =All!H10 -> 0
A6: =All!D11 -> 0 | B6: =All!E11 -> 0 | C6: =All!F11 -> 0 | D6: =All!G11 -> 0 | E6: =All!H11 -> 0
A7: =All!D12 -> 0 | B7: =All!E12 -> 0 | C7: =All!F12 -> 0 | D7: =All!G12 -> 0 | E7: =All!H12 -> 0
A8: =All!D13 -> 0 | B8: =All!E13 -> 0 | C8: =All!F13 -> 0 | D8: =All!G13 -> 0 | E8: =All!H13 -> 0
A9: =All!D14 -> 0 | B9: =All!E14 -> 0 | C9: =All!F14 -> 0 | D9: =All!G14 -> 0 | E9: =All!H14 -> 0
A10: =All!D15 -> 0 | B10: =All!E15 -> 0 | C10: =All!F15 -> 0 | D10: =All!G15 -> 0 | E10: =All!H15 -> 0
A11: =All!D16 -> 0 | B11: =All!E16 -> 0 | C11: =All!F16 -> 0 | D11: =All!G16 -> 0 | E11: =All!H16 -> 0
A12: =All!D17 -> 0 | B12: =All!E17 -> 0 | C12: =All!F17 -> 0 | D12: =All!G17 -> 0 | E12: =All!H17 -> 0
A13: =All!D19 -> 0 | B13: =All!E19 -> 0 | C13: =All!F19 -> 0 | D13: =All!G19 -> 0 | E13: =All!H19 -> 0
A14: =All!D20 -> 0 | B14: =All!E20 -> 0 | C14: =All!F20 -> 0 | D14: =All!G20 -> 0 | E14: =All!H20 -> 0
A15: =All!D21 -> 0 | B15: =All!E21 -> 0 | C15: =All!F21 -> 0 | D15: =All!G21 -> 0 | E15: =All!H21 -> 0
A16: =All!D22 -> 0 | B16: =All!E22 -> 0 | C16: =All!F22 -> 0 | D16: =All!G22 -> 0 | E16: =All!H22 -> 0
A17: =All!D23 -> 0 | B17: =All!E23 -> 0 | C17: =All!F23 -> 0 | D17: =All!G23 -> 0 | E17: =All!H23 -> 0
A18: =All!D24 -> 0 | B18: =All!E24 -> 0 | C18: =All!F24 -> 0 | D18: =All!G24 -> 0 | E18: =All!H24 -> 0
A19: =All!D25 -> 0 | B19: =All!E25 -> 0 | C19: =All!F25 -> 0 | D19: =All!G25 -> 0 | E19: =All!H25 -> 0
A20: =All!D26 -> 0 | B20: =All!E26 -> 0 | C20: =All!F26 -> 0 | D20: =All!G26 -> 0 | E20: =All!H26 -> 0
A21: =All!D27 -> 0 | B21: =All!E27 -> 0 | C21: =All!F27 -> 0 | D21: =All!G27 -> 0 | E21: =All!H27 -> 0
A22: =All!D28 -> 0 | B22: =All!E28 -> 0 | C22: =All!F28 -> 0 | D22: =All!G28 -> 0 | E22: =All!H28 -> 0
A23: =All!D29 -> 0 | B23: =All!E29 -> 0 | C23: =All!F29 -> 0 | D23: =All!G29 -> 0 | E23: =All!H29 -> 0
A24: =All!D30 -> 0 | B24: =All!E30 -> 0 | C24: =All!F30 -> 0 | D24: =All!G30 -> 0 | E24: =All!H30 -> 0
... A39: =All!D45 -> 0 | B39: =All!E45 -> 0 | C39: =All!F45 -> 0 | D39: =All!G45 -> 0 | E39: =All!H45 -> 0

Sheet All_Genotype
A1: LS_All
A2: Pos | B2: ='LS09'!AN3 -> LS09
A3: Gene | B3: ='LS09'!AN4 -> hapln1a
A4: F01 | B4: ='LS09'!AN5 -> ht
A5: F02 | B5: ='LS09'!AN6 -> ht
A6: F03 | B6: ='LS09'!AN7 -> ht
A7: F04 | B7: ='LS09'!AN8 -> ht
A8: F05 | B8: ='LS09'!AN9 -> ht
A9: F06 | B9: ='LS09'!AN10 -> ht
A10: F07 | B10: ='LS09'!AN11 -> wt
A11: F08 | B11: ='LS09'!AN12 -> ht
A12: F09 | B12: ='LS09'!AN13 -> ht
A13: F10 | B13: ='LS09'!AN14 -> mt
... A43: F40 | B43: ='LS09'!AN44 -> X
